<?xml version="1.0" ?>
<sdf version="1.4">
  <model name="velodyne_hdl-32e">
	<link name="base">
	  <pose>0 0 0.029335 0 0 0</pose>
	  <inertial>
		<mass>1.2</mass>
		<inertia>
		  <ixx>0.001087473</ixx>
          <iyy>0.001087473</iyy>
          <izz>0.001092437</izz>
		  <ixy>0</ixy>
		  <ixz>0</ixz>
		  <iyz>0</iyz>
		</inertia>
	  </inertial>
	  <collision name="base_collision">
		<geometry>
		  <cylinder>
			<radius>.04267</radius>
			<length>.05867</length>
		  </cylinder>
		</geometry>
	  </collision>

	  
	  <visual name="base_visual">
		<pose>0 0 -0.029335 0 0 0</pose>
		<geometry>
		  <mesh>
			<uri>model://meshes/HDL32E/base.dae</uri>
		  </mesh>
		</geometry>
	  </visual>
	</link>

	<link name="top">
	  <pose>0 0 0.095455 0 0 0</pose>
	  <inertial>
		<mass>0.1</mass>
		<inertia>
		  <ixx>0.000090623</ixx>
          <iyy>0.000090623</iyy>
          <izz>0.000091036</izz>
XS		  <ixy>0</ixy>
		  <ixz>0</ixz>
		  <iyz>0</iyz>
		</inertia>
	  </inertial>
	  <collision name="top_collision">
		<geometry>
		  <cylinder>
			<radius>0.04267</radius>
			<length>0.07357</length>
		  </cylinder>
		</geometry>
	  </collision>

	  <visual name="top_visual">
		<pose>0 0 -0.0376785 0 0 1.5707</pose>
		<geometry>
		  <mesh>
			<uri>model://meshes/HDL32E/top.dae</uri>
		  </mesh>
		</geometry>
	  </visual>

	  <sensor type="ray" name="sensor">
		<pose>0 0 -0.004645 1.5707 0 0</pose>
		<visualize>true</visualize>
		<update_rate>30</update_rate>
		<ray>
		  <noise>
			<type>gaussian</type>
			<mean>0.0</mean>
			<stddev>0.02</stddev>
		  </noise>
		  <scan>
			<horizontal>
			  <samples>32</samples>
			  <resolution>1</resolution>
			  <min_angle>-0.53529248</min_angle>
			  <max_angle>0.18622663</max_angle>
			</horizontal>
		  </scan>
		  <range>
			<min>1.0</min>
			<max>100</max>
			<resolution>0.02</resolution>
		  </range>
		</ray>

	  </sensor>
	</link>
	<joint type="revolute" name="joint">
	  <pose>0 0 -0.036785 0 0 0</pose>
	  <parent>base</parent>
	  <child>top</child>
	  <axis>
		<xyz>0 0 1</xyz>
	  </axis>
	</joint>
  </model>
</sdf>
